Workbook

Sheet Rules
A1: 1. Data laporan Stcok Alkes

Sheet REKON AP
A2: Customer | B2: No NPWP | C2: Item | D2: PO No. | E2: Date Invoice | F2: Invoice | G2: Date | H2: No Kwitansi | I2: Nilai Inv | J2: DPP | K2: DPP LAINNYA | L2: PPN Bendaharawan | M2: PPN | N2: PPh 23 | O2: PPh 22 | P2: Payment | Q2: DO.NO | R2: Code | S2: No Faktur | V2: Date | W2: Payment | X2: Description
A3: a
A4: RUMAH SAKIT UMUM DAERAH CIBINONG KABUPATEN BOGOR | B4: 656901832403000 | E4: 19/02/2025 | I4: =J4+L4 -> 10771251 | J4: 9703830 | K4: 8895178 | L4: 1067421 | O4: =J4*1.5% -> 145557.45 | P4: =J4+M4-O4 -> 9558272.6 | S4: 2.0025e+15
A5: DINAS KESEHATAN KABUPATEN BOGOR | B5: 1368901403000 | E5: 13/03/2025 | I5: =J5+L5 -> 6065000 | J5: 5463963 | K5: 5008632 | L5: 601037 | O5: =J5*1.5% -> 81959.445 | P5: =J5+M5-O5 -> 5382003.6 | S5: 2.0025001e+15
A6: DINAS KESEHATAN KABUPATEN BOGOR | B6: 1368901403000 | E6: 21/03/2025 | I6: =J6+L6 -> 865297061 | J6: 779546902 | K6: 714584660 | L6: 85750159 | O6: =J6*1.5% -> 11693204 | P6: =J6+M6-O6 -> 7.678537e+08 | S6: 2.0025001e+15
A7: DINAS KESEHATAN KABUPATEN BOGOR | B7: 1368901403000 | E7: 26/03/2025 | I7: =J7+L7 -> 17132001 | J7: 15434239 | K7: 14148011 | L7: 1697762 | O7: =J7*1.5% -> 231513.58 | P7: =J7+M7-O7 -> 15202725 | S7: 2.0025001e+15
A8: DINAS KESEHATAN KABUPATEN BOGOR | B8: 1368901403000 | E8: 45965 | I8: =J8+L8 -> 1342500 | J8: 1209459 | K8: 1108671 | L8: 133041 | O8: =J8*1.5% -> 18141.885 | P8: =J8+M8-O8 -> 1191317.1 | S8: 2.0025001e+15
A9: DINAS KESEHATAN KABUPATEN BOGOR | B9: 1368901403000 | E9: 17/04/2025 | I9: =J9+L9 -> 7254054 | J9: 6600000 | K9: 5450450 | L9: 654054 | O9: =J9*1.5% -> 99000 | P9: =J9+M9-O9 -> 6501000 | S9: 2.0025001e+15
A10: DINAS KESEHATAN KABUPATEN BOGOR | B10: 1368901403000 | E10: 17/04/2025 | I10: 6935500 | J10: =I10/1.11 -> 6248198.2 | K10: 5727515 | L10: 687302 | O10: =J10*1.5% -> 93722.973 | P10: =J10+M10-O10 -> 6154475.2 | S10: 2.0025001e+15
A11: DINAS KESEHATAN KABUPATEN BOGOR | B11: 1368901403000 | E11: 17/04/2025 | I11: =J11+L11 -> 1017766 | J11: 926000 | K11: 764715 | L11: 91766 | O11: =J11*1.5% -> 13890 | P11: =J11+M11-O11 -> 912110 | S11: 2.0025001e+15
A12: DINAS KESEHATAN KABUPATEN BOGOR | B12: 1368901403000 | E12: 17/04/2025 | I12: =J12+L12 -> 22652432 | J12: 20610000 | K12: 17020270 | L12: 2042432 | O12: =J12*1.5% -> 309150 | P12: =J12+M12-O12 -> 20300850 | S12: 2.0025001e+15
A13: DINAS KESEHATAN KABUPATEN BOGOR | B13: 1368901403000 | E13: 21/04/2025 | I13: =J13+L13 -> 55571499 | J13: 50064414 | K13: 45892379 | L13: 5507085 | O13: =J13*1.5% -> 750966.21 | P13: =J13+M13-O13 -> 49313448 | S13: 2.0025001e+15
A14: DINAS KESEHATAN KABUPATEN BOGOR | B14: 1368901403000 | E14: 21/04/2025 | I14: =J14+L14 -> 9955250 | J14: 8968694 | K14: 8221303 | L14: 986556 | O14: =J14*1.5% -> 134530.41 | P14: =J14+M14-O14 -> 8834163.6 | S14: 2.0025001e+15
A15: DINAS KESEHATAN KABUPATEN BOGOR | B15: 1368901403000 | E15: 23/04/2025 | I15: =J15+L15 -> 24749992 | J15: 22297290 | K15: 20439183 | L15: 2452702 | O15: =J15*1.5% -> 334459.35 | P15: =J15+M15-O15 -> 21962831 | S15: 2.0025001e+15
A16: Puskesmas Gobang | B16: 1368901403000 | E16: 22/05/2025 | I16: =J16+L16 -> 10982484 | J16: 9805657 | K16: 9805657 | L16: 1176827 | O16: =J16*1.5% -> 147084.86 | P16: =J16+M16-O16 -> 9658572.1 | S16: 2.0025002e+15
A17: DINAS KESEHATAN KABUPATEN BOGOR | B17: 1368901403000 | E17: 45694 | I17: =J17+L17 -> 4924998 | J17: 4436935 | K17: 4067190 | L17: 488063 | O17: =J17*1.5% -> 66554.025 | P17: =J17+M17-O17 -> 4370381 | S17: 2.0025002e+15
A18: DINAS KESEHATAN KABUPATEN BOGOR | B18: 1368901403000 | E18: 45694 | I18: =J18+L18 -> 1648500 | J18: 1485135 | K18: 1361373 | L18: 163365 | O18: =J18*1.5% -> 22277.025 | P18: =J18+M18-O18 -> 1462858 | S18: 2.0025002e+15
A19: RUMAH SAKIT UMUM DAERAH KOTA DUMAI | B19: 1211994212000 | E19: 45967 | I19: =J19+L19 -> 62128800 | J19: 55971892 | K19: 51307567 | L19: 6156908 | O19: =J19*1.5% -> 839578.38 | P19: =J19+M19-O19 -> 55132314 | S19: 4.0025002e+15
A20: DINAS KESEHATAN KABUPATEN BOGOR | B20: 1368901403000 | E20: 45997 | I20: =J20+L20 -> 1485135 | J20: 1485135 | K20: 1361374 | M20: 163365 | O20: =J20*1.5% -> 22277.025 | P20: =J20+M20-O20 -> 1626223 | S20: 2.0025002e+15
A21: DINAS KESEHATAN KABUPATEN BOGOR | B21: 1368901403000 | E21: 18/06/2025 | I21: =J21+L21 -> 688200 | J21: 620000 | K21: 568333 | L21: 68200 | O21: =J21*1.5% -> 9300 | P21: =J21+M21-O21 -> 610700 | S21: 2.0025002e+15
A22: DINAS KESEHATAN KABUPATEN BOGOR | B22: 1368901403000 | E22: 18/06/2025 | I22: =J22+L22 -> 4384500 | J22: 3950000 | K22: 3620833 | L22: 434500 | O22: =J22*1.5% -> 59250 | P22: =J22+M22-O22 -> 3890750 | S22: 2.0125002e+15
A23: DINAS KESEHATAN KABUPATEN BOGOR | B23: 1368901403000 | E23: 20/06/2025 | I23: =J23+L23 -> 8074140 | J23: 7274000 | K23: 6667834 | L23: 800140 | O23: =J23*1.5% -> 109110 | P23: =J23+M23-O23 -> 7164890 | S23: 2.0025002e+15
A24: DINAS KESEHATAN KABUPATEN BOGOR | B24: 1368901403000 | E24: 20/06/2025 | I24: =J24+L24 -> 3406000 | J24: 3068468 | K24: 2812763 | L24: 337532 | O24: =J24*1.5% -> 46027.02 | P24: =J24+M24-O24 -> 3022441 | S24: 2.0025002e+15
A25: DINAS KESEHATAN KABUPATEN BOGOR | B25: 1368901403000 | E25: 20/06/2025 | I25: =J25+L25 -> 6993000 | J25: 6300000 | K25: 5775000 | L25: 693000 | O25: =J25*1.5% -> 94500 | P25: =J25+M25-O25 -> 6205500 | S25: 2.0025002e+15
A26: DINAS KESEHATAN KABUPATEN BOGOR | B26: 1368901403000 | E26: 20/06/2025 | I26: =J26+L26 -> 31689997 | J26: 28549547 | K26: 26170419 | L26: 3140450 | O26: =J26*1.5% -> 428243.21 | P26: =J26+M26-O26 -> 28121304 | S26: 2.0025002e+15
A27: DINAS KESEHATAN KABUPATEN BOGOR | B27: 1368901403000 | E27: 24/06/2025 | I27: =J27+L27 -> 2763900 | J27: 2490000 | K27: 2282500 | L27: 273900 | O27: =J27*1.5% -> 37350 | P27: =J27+M27-O27 -> 2452650 | S27: 2.0025002e+15
A28: DINAS KESEHATAN KABUPATEN BOGOR | B28: 1368901403000 | E28: 45695 | I28: =J28+L28 -> 17040029 | J28: 15351380 | K28: 14072072 | L28: 1688649 | O28: =J28*1.5% -> 230270.7 | P28: =J28+M28-O28 -> 15121109 | S28: 2.0025002e+15
A29: PUSAT KESEHATAN MASYARAKAT BOGOR TENGAH KOTA BOGOR | B29: 606032910404000 | E29: 45754 | I29: =J29+L29 -> 300000 | J29: 270270 | K29: 247748 | L29: 29730 | O29: =J29*1.5% -> 4054.05 | P29: =J29+M29-O29 -> 266215.95 | S29: 2.0025002e+15
A30: RUMAH SAKIT UMUM DAERAH CIBINONG KABUPATEN BOGOR | B30: 656901832403000 | E30: 45876 | I30: =J30+L30 -> 72014070 | J30: 64877541 | K30: 59471079 | L30: 7136529 | O30: =J30*1.5% -> 973163.11 | P30: =J30+M30-O30 -> 63904378 | S30: 2.0025002e+15
A31: RUMAH SAKIT UMUM DAERAH CIBINONG KABUPATEN BOGOR | B31: 656901832403000 | E31: 45876 | I31: =J31+L31 -> 80066790 | J31: 72132243 | K31: 66121223 | L31: 7934547 | O31: =J31*1.5% -> 1081983.6 | P31: =J31+M31-O31 -> 71050259 | S31: 2.0025002e+15
A32: DINAS KESEHATAN KABUPATEN BOGOR | B32: 1368901403000 | E32: 15/07/2025 | I32: =J32+L32 -> 12699009 | J32: 11440550 | K32: 10487162 | L32: 1258459 | O32: =J32*1.5% -> 171608.25 | P32: =J32+M32-O32 -> 11268942 | S32: 2.0025002e+15
A33: DINAS KESEHATAN KABUPATEN BOGOR | B33: 1368901403000 | E33: 17/07/2025 | I33: =J33+L33 -> 8731260 | J33: 7866000 | K33: 7210500 | L33: 865260 | O33: =J33*1.5% -> 117990 | P33: =J33+M33-O33 -> 7748010 | S33: 2.0025002e+15
A34: DINAS KESEHATAN KABUPATEN BOGOR | B34: 1368901403000 | E34: 24/07/2025 | I34: =J34+L34 -> 38865469 | J34: 35013982 | K34: 32095721 | L34: 3851487 | O34: =J34*1.5% -> 525209.73 | P34: =J34+M34-O34 -> 34488772 | S34: 2.0025002e+15
A35: DINAS KESEHATAN KABUPATEN BOGOR | B35: 1368901403000 | E35: 28/07/2025 | I35: =J35+L35 -> 7152840 | J35: 6444000 | K35: 5907001 | L35: 708840 | O35: =J35*1.5% -> 96660 | P35: =J35+M35-O35 -> 6347340 | S35: 2.0025002e+15
A36: DINAS KESEHATAN KABUPATEN BOGOR | B36: 1368901403000 | E36: 13/08/2025 | I36: =J36+L36 -> 10782362 | J36: 9898200 | K36: 9073347 | L36: 884162 | O36: =J36*1.5% -> 148473 | P36: =J36+M36-O36 -> 9749727 | S36: 2.0025002e+15
A37: DINAS KESEHATAN KABUPATEN BOGOR | B37: 1368901403000 | E37: 13/08/2025 | I37: =J37+L37 -> 28081023 | J37: 25298241 | K37: 23189849 | L37: 2782782 | O37: =J37*1.5% -> 379473.61 | P37: =J37+M37-O37 -> 24918767 | S37: 2.0025003e+15
A38: DINAS KESEHATAN KABUPATEN BOGOR | B38: 1368901403000 | E38: 15/08/2025 | I38: =J38+L38 -> 8752855 | J38: 7908848 | K38: 7249759 | L38: 844007 | O38: =J38*1.5% -> 118632.72 | P38: =J38+M38-O38 -> 7790215.3 | S38: 2.0025003e+15
A39: DINAS KESEHATAN KABUPATEN BOGOR | B39: 1368901403000 | E39: 22/08/2025 | I39: =J39+L39 -> 8308380 | J39: 7894820 | K39: 7236878 | L39: 413560 | O39: =J39*1.5% -> 118422.3 | P39: =J39+M39-O39 -> 7776397.7 | S39: 2.0025003e+15
A40: DINAS KESEHATAN KABUPATEN BOGOR | B40: 1368901403000 | E40: 22/08/2025 | I40: =J40+L40 -> 2230001 | J40: 2009010 | K40: 1841592 | L40: 220991 | O40: =J40*1.5% -> 30135.15 | P40: =J40+M40-O40 -> 1978874.9 | S40: 2.0025003e+15
A41: DINAS KESEHATAN KABUPATEN BOGOR | B41: 1368901403000 | E41: 29/08/2025 | I41: =J41+L41 -> 10043002 | J41: 9047750 | K41: 8293768 | L41: 995252 | O41: =J41*1.5% -> 135716.25 | P41: =J41+M41-O41 -> 8912033.8 | S41: 2.0025003e+15
...

Sheet PURCHASES
A1: MPG BCA | B1: 4788883330
J2: Barang dan Jasa | K2: Jasa | N2: lampirkan link filenya disini
A3: Code | B3: Suppliers | C3: Item | D3: Date | E3: Sales Order | F3: PO No. | G3: Date Inv. | H3: Invoice | I3: Amount | J3: VAT | K3: PPH 23 | L3: A/P | M3: Date Invoice | N3: Link Document | O3: Status | P3: Remark
B4: Tokopedia | C4: Pembelian Termometer PKM Balekambang | G4: 45816 | I4: 705700 | L4: =I4+J4 -> 705700 | M4: =MONTH(G4) -> 6 | N4: Pembelian Termometer PKM | O4: Approved
B5: Shopee | C5: Pembelian Kursi, Meja dan Lemari PKM Gandoang | G5: 45882 | I5: 11381600 | L5: =I5+J5 -> 11381600 | M5: =MONTH(G5) -> 8 | N5: Pembelian Pesanan PKM Gandoang.pdf | O5: Approved
B6: Shopee | C6: Pembelian Composit Resin, Umblical, Bonding, Gludaten, Bisturi PKM DPT Saketi | E6: SURAT PESANAN PKM DPT SAKETI.jpeg | G6: 45882 | I6: 2654410 | L6: =I6+J6 -> 2654410 | M6: =MONTH(G6) -> 8 | N6: PKM DPT SAKETI.pdf | O6: Approved | Q6: 1322000
B7: PT. Top Point Medical | C7: TP Infusion Set Advance | E7: Surat Pesanan RSPP | F7: PO Infusion Set - Top Point | G7: 45880 | I7: 3040541 | J7: =I7*11% -> 334459.51 | L7: =I7+J7 -> 3375000.5 | M7: =MONTH(G7) -> 8 | N7: Invoice Top Point | O7: Approved | P7: FP Infusion Set - Top Point
B8: Shopee | C8: Pembelian Gludenta DPT Saketi | E8: part of SO no.3 | G8: 45882 | I8: 1408256 | L8: =I8+J8 -> 1408256 | M8: =MONTH(G8) -> 8 | N8: Gludenta | O8: Approved
B9: Top Point | C9: Pembelian Suntikan DPT Saketi | E9: part of SO no.3 | G9: 45888 | I9: 136554 | J9: =I9*11% -> 15020.94 | L9: =I9+J9 -> 151574.94 | M9: =MONTH(G9) -> 8 | N9: 22-08-1015 (pembelian top point) | O9: Approved | P9: FP - Top Point.pdf
B10: Sarana Megamedilab Sejahtera (SMS) | C10: Pembelian Lampu | E10: RSUD Cibinong | G10: 45869 | I10: 2800000 | J10: =I10*11% -> 308000 | L10: 3108000 | M10: =MONTH(G10) -> 7 | N10: Invoice SMS | O10: Approved | P10: FP - PT. SMS
B11: Shopee | C11: Pembelian Pesanan Plastik (PKM Cimandala) | E11: -Menyusul- | G11: 45895 | I11: 2021100 | L11: 2021100 | M11: =MONTH(G11) -> 8 | N11: Pesanan PKM Cimandala | O11: Approved
B12: Shopee | C12: Pembelian Yellow dan Blue Tip (PKM Cangkurawok) | E12: surat-pesanan-EP-01K387EQ0896Y44BX6R9RSJ2FA (Pkm Cangkurawok) | G12: 45895 | I12: 82499 | L12: 82499 | M12: =MONTH(G12) -> 8 | N12: Pembelanjaan yellow dan blue tip (pkm cangkurawok) 26/8/25 | O12: Approved
B13: Shopee | C13: Pembelanjaan Pesanan (PKM Pasir Angin) | E13: surat-pesanan-EP-01K381B70E6329EG57Q86XG5DH.pdf (PKM Pasir angin) 27-08-25 | G13: 45896 | I13: 1086000 | L13: 1086000 | M13: =MONTH(G13) -> 8 | N13: Pembelanjaan Pesanan PKM Pasir Angin 27-08-25 | O13: Approved
B14: Top Point | C14: Pembelian TP Infusion Set Advance (RSPP) | E14: Surat Pesanan RSPP PO 2 (20-08-25) | F14: PO ke Top Point (20-08-25) | G14: 45890 | I14: 3040541 | J14: 334459 | L14: =I14+J14 -> 3375000 | M14: =MONTH(G14) -> 8 | N14: Invoice TP (21-08-25) | O14: Approved | P14: FP - Top Point (21-08-25)
B15: PT Demaz Noer Abadi | C15: Pembelian Pesanan (PKM Karyamekar) Test Strip | E15: Pesanan PKM Karya Mekar (28-08-25) | F15: PO MPG-270825008 Biosensor.pdf | G15: 45897 | I15: 700000 | J15: 77000 | L15: =I15+J15 -> 777000 | M15: =MONTH(G15) -> 8 | N15: inv biosensor | O15: Approved | P15: follow up FPnya danis
B16: PT. Elba Lab Medika | C16: Pembelian Pesanan (PKM Ciawi ) Uric acid dan Glucose | E16: surat-pesanan-EP-01K3Q5WHEXQ3VZNQBKWARSAMDH Pkm Ciawi Erba.pdf | F16: PO MPG-270825006 Elba Medika Revisi.pdf | G16: 45896 | I16: 6088810 | J16: 669769 | L16: =I16+J16 -> 6758579 | M16: =MONTH(G16) -> 8 | N16: Inv Elba | O16: Approved | P16: follow up FPnya danis
B17: Shopee | C17: Pembelian Pesanan (PKM Karyamekar) Alcohol swab, blue dan yellow tip | E17: part of SO no.15 | G17: 45896 | I17: 206508 | L17: =I17+J17 -> 206508 | M17: =MONTH(G17) -> 8 | N17: Pembelanjaan PKM Karyamekar (sp 27-08-25) | O17: Approved
B18: Shopee | C18: Pembelian Pesanan (PKM Pasir Angin) Apar 3kg | E18: surat-pesanan-EP-01K3T38R3TQ03RS3GZPYQRVWJ9 PKM Pasir Angin (Apar) | G18: 45898 | I18: 541000 | L18: =I18+J18 -> 541000 | M18: =MONTH(G18) -> 8 | N18: PKM Pasir Angin - Apar 3kg | O18: Approved
B19: PT. Burhan Sejahtera Mulia | C19: Pembelian Pesanan (PKM Karyamekar) Vacum Tube Plain | E19: Patt of SO np.15 | F19: PO ke PT. BSM (vacum tube) | G19: 45898 | I19: 425000 | J19: 46750 | L19: =I19+J19 -> 471750 | M19: =MONTH(G19) -> 8 | N19: inv bsm (vacume tube) | O19: Approved | P19: fp akan di fu setelah barang tiba
B20: Shopee | C20: Pembelian Pesanan (PKM Bojong) cover glass dan bisturi | E20: Surat Pesanan PKM Bojong (3 Sep 2025) | G20: 45903 | I20: 96580 | L20: =I20+J20 -> 96580 | M20: =MONTH(G20) -> 9 | N20: Bisturi dan Cover glass PKM Bojong | O20: Approved
B21: Shopee | C21: Pembelian Pesanan (PKM Bojong) kassa steril | E21: Surat Pesanan PKM Bojong (3 Sep 2025) | G21: 45903 | I21: 402500 | L21: =I21+J21 -> 402500 | M21: =MONTH(G21) -> 9 | N21: Kassa Steril PKM Bojong | O21: Approved
B22: Toko Pramuka | C22: Pembelian Pesanan (PKM Sentul) 10box Safeguard | E22: -Menyusul- | G22: 45903 | I22: 430000 | L22: =I22+J22 -> 430000 | M22: =MONTH(G22) -> 9 | N22: Safeguard PKM Sentul | O22: Approved | P22: ditunda dl
B23: Top Point | C23: Pembelian Pesanan (RSPP) PO ke 3 | E23: Surat Pesanan RSPP (PO 3) | F23: PO ke Top Point (Pesanan RSPP PO 3) | G23: 45896 | I23: 6081081 | J23: 668919 | L23: =I23+J23 -> 6750000 | M23: =MONTH(G23) -> 8 | N23: Inv TP (PO 3 RSPP) | O23: Approved | P23: FP - Top Point (PO 3 RSPP)
B24: Top Point | C24: Pembelian Kekurangan Stock Suntikan RSUD | E24: Surat Pesanan Suntikan RSUD Cibinong | F24: PO ke TOP POINT (stok suntikan rsud) | G24: 45897 | I24: 3386086 | J24: 372469 | L24: =I24+J24 -> 3758555 | M24: =MONTH(G24) -> 8 | N24: Inv TP (stok suntikan rsud) | O24: Approved | P24: FP TP (stok suntikan rsud)
B25: Sarana Megamedilab Sejahtera (SMS) | C25: Pembelian Reagen RSUD Cibinong (Nodin 15) | D25: SPH RSUD CIBINONG NODIN 15 (1).pdf | E25: nodin 15 rsud cibinong | F25: PO ke SMS (nodin 15 RSUD Cibinong) | G25: 45876 | I25: 12284010 | J25: 1351241 | L25: =I25+J25 -> 13635251 | M25: =MONTH(G25) -> 8 | N25: inv sms | O25: Approved | P25: FP SMS (nodin 15 RSUD Cibinong)
B26: PT. Burhan Sejahtera Mulia | C26: Pembelian Pesanan (PKM Bojong) Reagen Asam Urat | E26: part of SO no.20 | F26: PO MPG-080925003 BSM.pdf | G26: 45908 | I26: 720440 | J26: 79248 | L26: =I26+J26 -> 799688 | M26: =MONTH(G26) -> 9 | N26: Inv BSM | O26: Approved | P26: akan di follow up
B27: Shopee | C27: Pembelanjaan Pesanan Tambahan (PKM Bojong) Carpule dan Plastik Sampah Medis | E27: -Menyusul- | G27: 45908 | I27: 543000 | L27: =I27 -> 543000 | M27: =MONTH(G27) -> 9 | N27: Pesanan Tambahan PKM Bojong | O27: Approved
B28: PT. Tirta Investama | C28: Pembaayaran Aqua Galon Gedung | G28: 45900 | I28: 400000 | L28: =I28 -> 400000 | M28: =MONTH(G28) -> 8 | N28: inv aqua | O28: Approved | P28: fp aqua
B29: PT. Top Point Medical | C29: Pembellian Pesanan (RSPP) PO ke 4 | E29: PO KE 4 RSPP | F29: po ke tp (rspp ke 4) | G29: 45909 | I29: 4560811 | J29: 501689 | L29: =I29+J29 -> 5062500 | M29: =MONTH(G29) -> 9 | N29: INV TP : 034/TPM/IX/2025 | O29: Approved | P29: FP TP : 04002500280251436
B30: Gedung | C30: Pembayaran Listrik dan Parkir Gedung (pemakaian agustus) | G30: 45915 | I30: 4684781 | L30: =I30 -> 4684781 | M30: =MONTH(G30) -> 9 | N30: listrik parkir agustus.pdf | O30: Approved
B31: Shopee | C31: Pembelian Kekurangan Plastik Sampah Medis (PKM Bojong) | E31: NOTA PERABOT KANTOR MATA PENSIL 09 25.pdf | G31: 45915 | I31: 53380 | L31: =I31 -> 53380 | M31: =MONTH(G31) -> 9 | N31: Pembelian Kekurangan Plastik PKM Bojong | O31: Approved
B32: Shopee | C32: Pembelian Kontrol Kimia (PKM Balekambang) | E32: Pesanan Balekambang | G32: 45916 | I32: 1277500 | L32: =I32 -> 1277500 | M32: =MONTH(G32) -> 9 | N32: Kontrol Kimia | O32: Approved
B33: Shopee | C33: Pembelian Pesanan (PKM Cipeucang) | E33: Surat Pesanan BMHP PKM Cipeucang.pdf | G33: 45917 | I33: 2676315 | L33: =I33 -> 2676315 | M33: =MONTH(G33) -> 9 | N33: Pembelanjaan Pesanan PKM Cipeucang.pdf | O33: Approved
B34: Shopee | C34: Pembelian Pesanan (PKM Kelapa Dua) Plastik Sampah | E34: SP Belanja Kebersihan Puskesmas Kelapa Dua September 2025.pdf | G34: 45925 | I34: 1827490 | L34: 1827490 | M34: =MONTH(G34) -> 9 | N34: plastik sampah pkm kelapa dua.pdf | O34: Approved
B35: Shopee | C35: Pembelian Pesanan (PKM Kelapa Dua) Pengharum Ruangan spray dan gantung dahlia | E35: SP Belanja Kebersihan Puskesmas Kelapa Dua September 2025.pdf | G35: 45925 | I35: 937200 | L35: 937200 | M35: =MONTH(G35) -> 9 | N35: Pengahrum spray dan gantung Dahlia | O35: Approved
B36: Shopee | C36: Pembelian Pesanan (PKM Kelapa Dua) tissue livi dan paseo | E36: SP Belanja Kebersihan Puskesmas Kelapa Dua September 2025.pdf | G36: 45925 | I36: 480255 | L36: 480255 | M36: =MONTH(G36) -> 9 | N36: tissue livi dan paseo.pdf | O36: Approved
B37: Shopee | C37: Pembelian Pesanan (PKM Kelapa Dua) Baygon | E37: SP Belanja Kebersihan Puskesmas Kelapa Dua September 2025.pdf | G37: 45925 | I37: 798000 | L37: 798000 | M37: =MONTH(G37) -> 9 | N37: baygon.pdf | O37: Approved
B38: Shopee | C38: Pembelian Pesanan (PKM Kelapa Dua) switzal dan minyak telon | E38: SP Belanja Kebersihan Puskesmas Kelapa Dua September 2025.pdf | G38: 45925 | I38: 493200 | L38: 493200 | M38: =MONTH(G38) -> 9 | N38: switzal dan minyak telon.pdf | O38: Approved
B39: Shopee | C39: Pembelian Pesanan (PKM Kelapa Dua) kamper | E39: SP Belanja Kebersihan Puskesmas Kelapa Dua September 2025.pdf | G39: 45925 | I39: 622900 | L39: 622900 | M39: =MONTH(G39) -> 9 | N39: kamper dan pewangi kopi.pdf | O39: Approved
B40: Shopee | C40: Pembelian Pesanan (PKM Kelapa Dua) tempat sampah | E40: SP Belanja Kebersihan Puskesmas Kelapa Dua September 2025.pdf | G40: 45925 | I40: 432000 | L40: 432000 | M40: =MONTH(G40) -> 9 | N40: tempat sampah shinpo | O40: Approved
...

Sheet APOutstanding
B1: OTOMATIS DARI SHEET PURCHASE | U1: Lampirkan BUKTI BAYAR
I2: Amount | M2: Payment | R2: A/P | S2: Remark | T2: Remark | U2: Link
A3: Code | B3: Suppliers | C3: Item | D3: Date | E3: Sales Order | F3: PO No. | G3: Date PO | H3: Invoice | I3: Rp | J3: VAT | K3: PPH 23 | L3: A/P | M3: Date | N3: By | O3: Rp | P3: Date | Q3: Other | R3: Outstanding | U3: Document
A4: =PURCHASES!A4 | B4: =IFERROR(__xludf.DUMMYFUNCTION("QUERY(PURCHASES!B4:L253)"),"Tokopedia") -> Tokopedia | C4: =IFERROR(__xludf.DUMMYFUNCTION("""COMPUTED_VALUE"""),"Pembelian Termometer PKM Balekambang") -> Pembelian Termometer PKM Balekambang | G4: =IFERROR(__xludf.DUMMYFUNCTION("""COMPUTED_VALUE"""),45816.0) -> 45816 | I4: =IFERROR(__xludf.DUMMYFUNCTION("""COMPUTED_VALUE"""),705700.0) -> 705700 | L4: =IFERROR(__xludf.DUMMYFUNCTION("""COMPUTED_VALUE"""),705700.0) -> 705700 | M4: 11-agustus-25 | N4: BCA MPG | O4: 705700 | P4: 11-agus-25 | R4: =L4-O4 -> 0 | S4: =IF(#REF!>0,"ost","-") -> #REF! | T4: - | U4: Pembelian Termometer PKM
B5: =IFERROR(__xludf.DUMMYFUNCTION("""COMPUTED_VALUE"""),"Shopee") -> Shopee | C5: =IFERROR(__xludf.DUMMYFUNCTION("""COMPUTED_VALUE"""),"Pembelian Kursi, Meja dan Lemari PKM Gandoang ") -> Pembelian Kursi, Meja dan Lemari PKM Gandoang | G5: =IFERROR(__xludf.DUMMYFUNCTION("""COMPUTED_VALUE"""),45882.0) -> 45882 | I5: =IFERROR(__xludf.DUMMYFUNCTION("""COMPUTED_VALUE"""),1.13816E7) -> 11381600 | L5: =IFERROR(__xludf.DUMMYFUNCTION("""COMPUTED_VALUE"""),1.13816E7) -> 11381600 | M5: 11-agustus-25 | N5: BCA MPG | O5: 11381600 | P5: 11-agustus-25 | R5: =L5-O5 -> 0 | S5: =IF(R5>0,"ost","-") -> - | T5: - | U5: Pembelian Pesanan PKM Gandoang.pdf
A6: =PURCHASES!A6 | B6: =IFERROR(__xludf.DUMMYFUNCTION("""COMPUTED_VALUE"""),"Shopee") -> Shopee | C6: =IFERROR(__xludf.DUMMYFUNCTION("""COMPUTED_VALUE"""),"Pembelian Composit Resin, Umblical, Bonding, Gludaten, Bisturi PKM DPT Saketi") -> Pembelian Composit Resin, Umblical, Bonding, Gludaten, Bisturi PKM DPT Saketi | E6: =IFERROR(__xludf.DUMMYFUNCTION("""COMPUTED_VALUE"""),"SURAT PESANAN PKM DPT SAKETI.jpeg") -> SURAT PESANAN PKM DPT SAKETI.jpeg | G6: =IFERROR(__xludf.DUMMYFUNCTION("""COMPUTED_VALUE"""),45882.0) -> 45882 | I6: =IFERROR(__xludf.DUMMYFUNCTION("""COMPUTED_VALUE"""),2654410.0) -> 2654410 | L6: =IFERROR(__xludf.DUMMYFUNCTION("""COMPUTED_VALUE"""),2654410.0) -> 2654410 | M6: 11-agustus-25 | N6: BCA MPG | O6: 2654410 | P6: 11-agustus-25 | R6: =L6-O6 -> 0 | S6: =IF(R6>0,"ost","-") -> - | T6: - | U6: Bukti TF Pesanan PKM DPT Saketi.pdf
A7: =PURCHASES!A7 | B7: =IFERROR(__xludf.DUMMYFUNCTION("""COMPUTED_VALUE"""),"PT. Top Point Medical") -> PT. Top Point Medical | C7: =IFERROR(__xludf.DUMMYFUNCTION("""COMPUTED_VALUE"""),"TP Infusion Set Advance") -> TP Infusion Set Advance | E7: =IFERROR(__xludf.DUMMYFUNCTION("""COMPUTED_VALUE"""),"Surat Pesanan RSPP") -> Surat Pesanan RSPP | F7: =IFERROR(__xludf.DUMMYFUNCTION("""COMPUTED_VALUE"""),"PO Infusion Set - Top Point") -> PO Infusion Set - Top Point | G7: =IFERROR(__xludf.DUMMYFUNCTION("""COMPUTED_VALUE"""),45880.0) -> 45880 | I7: =IFERROR(__xludf.DUMMYFUNCTION("""COMPUTED_VALUE"""),3040541.0) -> 3040541 | J7: =IFERROR(__xludf.DUMMYFUNCTION("""COMPUTED_VALUE"""),334459.51) -> 334459.51 | L7: =IFERROR(__xludf.DUMMYFUNCTION("""COMPUTED_VALUE"""),3375000.51) -> 3375000.5 | M7: 11-agustus-25 | N7: BCA MPG | O7: 3375000 | P7: 11-agustus-25 | R7: =L7-O7 -> 0.51 | S7: =IF(R7>0,"ost","-") -> ost | T7: - | U7: Pembayaran ke Top Point
A8: =PURCHASES!A8 | B8: =IFERROR(__xludf.DUMMYFUNCTION("""COMPUTED_VALUE"""),"Shopee") -> Shopee | C8: =IFERROR(__xludf.DUMMYFUNCTION("""COMPUTED_VALUE"""),"Pembelian Gludenta DPT Saketi") -> Pembelian Gludenta DPT Saketi | E8: =IFERROR(__xludf.DUMMYFUNCTION("""COMPUTED_VALUE"""),"part of SO no.3") -> part of SO no.3 | G8: =IFERROR(__xludf.DUMMYFUNCTION("""COMPUTED_VALUE"""),45882.0) -> 45882 | I8: =IFERROR(__xludf.DUMMYFUNCTION("""COMPUTED_VALUE"""),1408256.0) -> 1408256 | L8: =IFERROR(__xludf.DUMMYFUNCTION("""COMPUTED_VALUE"""),1408256.0) -> 1408256 | M8: 11-agustus-25 | N8: BCA MPG | O8: 1408256 | P8: 11-agustus-25 | R8: =L8-O8 -> 0 | S8: =IF(R8>0,"ost","-") -> - | T8: - | U8: Bukti Bayar Gludenta
B9: =IFERROR(__xludf.DUMMYFUNCTION("""COMPUTED_VALUE"""),"Top Point") -> Top Point | C9: =IFERROR(__xludf.DUMMYFUNCTION("""COMPUTED_VALUE"""),"Pembelian Suntikan DPT Saketi") -> Pembelian Suntikan DPT Saketi | E9: =IFERROR(__xludf.DUMMYFUNCTION("""COMPUTED_VALUE"""),"part of SO no.3") -> part of SO no.3 | G9: =IFERROR(__xludf.DUMMYFUNCTION("""COMPUTED_VALUE"""),45888.0) -> 45888 | I9: =IFERROR(__xludf.DUMMYFUNCTION("""COMPUTED_VALUE"""),136554.0) -> 136554 | J9: =IFERROR(__xludf.DUMMYFUNCTION("""COMPUTED_VALUE"""),15020.94) -> 15020.94 | L9: =IFERROR(__xludf.DUMMYFUNCTION("""COMPUTED_VALUE"""),151574.94) -> 151574.94 | M9: 11-agustus-25 | N9: BCA MPG | O9: 151575 | P9: 11-agustus-25 | R9: =L9-O9 -> -0.06 | S9: =IF(R9>0,"ost","-") -> - | T9: - | U9: Bukti Bayar Top Point
B10: =IFERROR(__xludf.DUMMYFUNCTION("""COMPUTED_VALUE"""),"Sarana Megamedilab Sejahtera (SMS)") -> Sarana Megamedilab Sejahtera (SMS) | C10: =IFERROR(__xludf.DUMMYFUNCTION("""COMPUTED_VALUE"""),"Pembelian Lampu ") -> Pembelian Lampu | E10: =IFERROR(__xludf.DUMMYFUNCTION("""COMPUTED_VALUE"""),"RSUD Cibinong") -> RSUD Cibinong | G10: =IFERROR(__xludf.DUMMYFUNCTION("""COMPUTED_VALUE"""),45869.0) -> 45869 | I10: =IFERROR(__xludf.DUMMYFUNCTION("""COMPUTED_VALUE"""),2800000.0) -> 2800000 | J10: =IFERROR(__xludf.DUMMYFUNCTION("""COMPUTED_VALUE"""),308000.0) -> 308000 | L10: =IFERROR(__xludf.DUMMYFUNCTION("""COMPUTED_VALUE"""),3108000.0) -> 3108000 | M10: 11-agustus-25 | N10: BCA MPG | O10: 3108000 | P10: 11-agustus-25 | R10: =L10-O10 -> 0 | S10: =IF(R10>0,"ost","-") -> - | T10: -
B11: =IFERROR(__xludf.DUMMYFUNCTION("""COMPUTED_VALUE"""),"Shopee") -> Shopee | C11: =IFERROR(__xludf.DUMMYFUNCTION("""COMPUTED_VALUE"""),"Pembelian Pesanan Plastik (PKM Cimandala)") -> Pembelian Pesanan Plastik (PKM Cimandala) | E11: =IFERROR(__xludf.DUMMYFUNCTION("""COMPUTED_VALUE"""),"-Menyusul-") -> -Menyusul- | G11: =IFERROR(__xludf.DUMMYFUNCTION("""COMPUTED_VALUE"""),45895.0) -> 45895 | I11: =IFERROR(__xludf.DUMMYFUNCTION("""COMPUTED_VALUE"""),2021100.0) -> 2021100 | L11: =IFERROR(__xludf.DUMMYFUNCTION("""COMPUTED_VALUE"""),2021100.0) -> 2021100 | M11: 11-agustus-25 | N11: BCA MPG | O11: 2021100 | P11: 11-agustus-25 | R11: =L11-O11 -> 0 | S11: =IF(R11>0,"ost","-") -> - | T11: -
B12: =IFERROR(__xludf.DUMMYFUNCTION("""COMPUTED_VALUE"""),"Shopee") -> Shopee | C12: =IFERROR(__xludf.DUMMYFUNCTION("""COMPUTED_VALUE"""),"Pembelian Yellow dan Blue Tip (PKM Cangkurawok)") -> Pembelian Yellow dan Blue Tip (PKM Cangkurawok) | E12: =IFERROR(__xludf.DUMMYFUNCTION("""COMPUTED_VALUE"""),"surat-pesanan-EP-01K387EQ0896Y44BX6R9RSJ2FA (Pkm Cangkurawok)") -> surat-pesanan-EP-01K387EQ0896Y44BX6R9RSJ2FA (Pkm Cangkurawok) | G12: =IFERROR(__xludf.DUMMYFUNCTION("""COMPUTED_VALUE"""),45895.0) -> 45895 | I12: =IFERROR(__xludf.DUMMYFUNCTION("""COMPUTED_VALUE"""),82499.0) -> 82499 | L12: =IFERROR(__xludf.DUMMYFUNCTION("""COMPUTED_VALUE"""),82499.0) -> 82499 | M12: 11-agustus-25 | N12: BCA MPG | O12: 82499 | P12: 11-agustus-25 | R12: =L12-O12 -> 0 | S12: =IF(R12>0,"ost","-") -> - | T12: -
B13: =IFERROR(__xludf.DUMMYFUNCTION("""COMPUTED_VALUE"""),"Shopee") -> Shopee | C13: =IFERROR(__xludf.DUMMYFUNCTION("""COMPUTED_VALUE"""),"Pembelanjaan Pesanan (PKM Pasir Angin)") -> Pembelanjaan Pesanan (PKM Pasir Angin) | E13: =IFERROR(__xludf.DUMMYFUNCTION("""COMPUTED_VALUE"""),"surat-pesanan-EP-01K381B70E6329EG57Q86XG5DH.pdf (PKM Pasir angin) 27-08-25") -> surat-pesanan-EP-01K381B70E6329EG57Q86XG5DH.pdf (PKM Pasir angin) 27-08-25 | G13: =IFERROR(__xludf.DUMMYFUNCTION("""COMPUTED_VALUE"""),45896.0) -> 45896 | I13: =IFERROR(__xludf.DUMMYFUNCTION("""COMPUTED_VALUE"""),1086000.0) -> 1086000 | L13: =IFERROR(__xludf.DUMMYFUNCTION("""COMPUTED_VALUE"""),1086000.0) -> 1086000 | M13: 11-agustus-25 | N13: BCA MPG | O13: 1086000 | P13: 11-agustus-25 | R13: =L13-O13 -> 0 | S13: =IF(R13>0,"ost","-") -> - | T13: -
B14: =IFERROR(__xludf.DUMMYFUNCTION("""COMPUTED_VALUE"""),"Top Point") -> Top Point | C14: =IFERROR(__xludf.DUMMYFUNCTION("""COMPUTED_VALUE"""),"Pembelian TP Infusion Set Advance (RSPP)") -> Pembelian TP Infusion Set Advance (RSPP) | E14: =IFERROR(__xludf.DUMMYFUNCTION("""COMPUTED_VALUE"""),"Surat Pesanan RSPP PO 2 (20-08-25)") -> Surat Pesanan RSPP PO 2 (20-08-25) | F14: =IFERROR(__xludf.DUMMYFUNCTION("""COMPUTED_VALUE"""),"PO ke Top Point (20-08-25)") -> PO ke Top Point (20-08-25) | G14: =IFERROR(__xludf.DUMMYFUNCTION("""COMPUTED_VALUE"""),45890.0) -> 45890 | I14: =IFERROR(__xludf.DUMMYFUNCTION("""COMPUTED_VALUE"""),3040541.0) -> 3040541 | J14: =IFERROR(__xludf.DUMMYFUNCTION("""COMPUTED_VALUE"""),334459.0) -> 334459 | L14: =IFERROR(__xludf.DUMMYFUNCTION("""COMPUTED_VALUE"""),3375000.0) -> 3375000 | M14: 11-agustus-25 | N14: BCA MPG | O14: 3375000 | P14: 11-agustus-25 | R14: =L14-O14 -> 0 | S14: =IF(R14>0,"ost","-") -> - | T14: -
B15: =IFERROR(__xludf.DUMMYFUNCTION("""COMPUTED_VALUE"""),"PT Demaz Noer Abadi") -> PT Demaz Noer Abadi | C15: =IFERROR(__xludf.DUMMYFUNCTION("""COMPUTED_VALUE"""),"Pembelian Pesanan (PKM Karyamekar) Test Strip") -> Pembelian Pesanan (PKM Karyamekar) Test Strip | E15: =IFERROR(__xludf.DUMMYFUNCTION("""COMPUTED_VALUE"""),"Pesanan PKM Karya Mekar (28-08-25)") -> Pesanan PKM Karya Mekar (28-08-25) | F15: =IFERROR(__xludf.DUMMYFUNCTION("""COMPUTED_VALUE"""),"PO MPG-270825008 Biosensor.pdf") -> PO MPG-270825008 Biosensor.pdf | G15: =IFERROR(__xludf.DUMMYFUNCTION("""COMPUTED_VALUE"""),45897.0) -> 45897 | I15: =IFERROR(__xludf.DUMMYFUNCTION("""COMPUTED_VALUE"""),700000.0) -> 700000 | J15: =IFERROR(__xludf.DUMMYFUNCTION("""COMPUTED_VALUE"""),77000.0) -> 77000 | L15: =IFERROR(__xludf.DUMMYFUNCTION("""COMPUTED_VALUE"""),777000.0) -> 777000 | M15: 11-agustus-25 | N15: BCA MPG | O15: 777000 | P15: 11-agustus-25 | R15: =L15-O15 -> 0 | S15: =IF(R15>0,"ost","-") -> - | T15: -
B16: =IFERROR(__xludf.DUMMYFUNCTION("""COMPUTED_VALUE"""),"PT. Elba Lab Medika") -> PT. Elba Lab Medika | C16: =IFERROR(__xludf.DUMMYFUNCTION("""COMPUTED_VALUE"""),"Pembelian Pesanan (PKM Ciawi ) Uric acid dan Glucose") -> Pembelian Pesanan (PKM Ciawi ) Uric acid dan Glucose | E16: =IFERROR(__xludf.DUMMYFUNCTION("""COMPUTED_VALUE"""),"surat-pesanan-EP-01K3Q5WHEXQ3VZNQBKWARSAMDH Pkm Ciawi Erba.pdf") -> surat-pesanan-EP-01K3Q5WHEXQ3VZNQBKWARSAMDH Pkm Ciawi Erba.pdf | F16: =IFERROR(__xludf.DUMMYFUNCTION("""COMPUTED_VALUE"""),"PO MPG-270825006 Elba Medika Revisi.pdf") -> PO MPG-270825006 Elba Medika Revisi.pdf | G16: =IFERROR(__xludf.DUMMYFUNCTION("""COMPUTED_VALUE"""),45896.0) -> 45896 | I16: =IFERROR(__xludf.DUMMYFUNCTION("""COMPUTED_VALUE"""),6088810.0) -> 6088810 | J16: =IFERROR(__xludf.DUMMYFUNCTION("""COMPUTED_VALUE"""),669769.0) -> 669769 | L16: =IFERROR(__xludf.DUMMYFUNCTION("""COMPUTED_VALUE"""),6758579.0) -> 6758579 | M16: 11-agustus-25 | N16: BCA MPG | O16: 6758579 | P16: 11-agustus-25 | R16: =L16-O16 -> 0 | S16: =IF(R16>0,"ost","-") -> - | T16: -
B17: =IFERROR(__xludf.DUMMYFUNCTION("""COMPUTED_VALUE"""),"Shopee") -> Shopee | C17: =IFERROR(__xludf.DUMMYFUNCTION("""COMPUTED_VALUE"""),"Pembelian Pesanan (PKM Karyamekar) Alcohol swab, blue dan yellow tip") -> Pembelian Pesanan (PKM Karyamekar) Alcohol swab, blue dan yellow tip | E17: =IFERROR(__xludf.DUMMYFUNCTION("""COMPUTED_VALUE"""),"part of SO no.15") -> part of SO no.15 | G17: =IFERROR(__xludf.DUMMYFUNCTION("""COMPUTED_VALUE"""),45896.0) -> 45896 | I17: =IFERROR(__xludf.DUMMYFUNCTION("""COMPUTED_VALUE"""),206508.0) -> 206508 | L17: =IFERROR(__xludf.DUMMYFUNCTION("""COMPUTED_VALUE"""),206508.0) -> 206508 | M17: 11-agustus-25 | N17: BCA MPG | O17: 206508 | P17: 11-agustus-25 | R17: =L17-O17 -> 0 | S17: =IF(R17>0,"ost","-") -> - | T17: -
B18: =IFERROR(__xludf.DUMMYFUNCTION("""COMPUTED_VALUE"""),"Shopee ") -> Shopee | C18: =IFERROR(__xludf.DUMMYFUNCTION("""COMPUTED_VALUE"""),"Pembelian Pesanan (PKM Pasir Angin) Apar 3kg") -> Pembelian Pesanan (PKM Pasir Angin) Apar 3kg | E18: =IFERROR(__xludf.DUMMYFUNCTION("""COMPUTED_VALUE"""),"surat-pesanan-EP-01K3T38R3TQ03RS3GZPYQRVWJ9 PKM Pasir Angin (Apar)") -> surat-pesanan-EP-01K3T38R3TQ03RS3GZPYQRVWJ9 PKM Pasir Angin (Apar) | G18: =IFERROR(__xludf.DUMMYFUNCTION("""COMPUTED_VALUE"""),45898.0) -> 45898 | I18: =IFERROR(__xludf.DUMMYFUNCTION("""COMPUTED_VALUE"""),541000.0) -> 541000 | L18: =IFERROR(__xludf.DUMMYFUNCTION("""COMPUTED_VALUE"""),541000.0) -> 541000 | M18: 45901 | N18: BCA MPG | O18: 541000 | P18: 45901 | R18: =L18-O18 -> 0 | S18: =IF(R18>0,"ost","-") -> - | T18: -
B19: =IFERROR(__xludf.DUMMYFUNCTION("""COMPUTED_VALUE"""),"PT. Burhan Sejahtera Mulia") -> PT. Burhan Sejahtera Mulia | C19: =IFERROR(__xludf.DUMMYFUNCTION("""COMPUTED_VALUE"""),"Pembelian Pesanan (PKM Karyamekar) Vacum Tube Plain") -> Pembelian Pesanan (PKM Karyamekar) Vacum Tube Plain | E19: =IFERROR(__xludf.DUMMYFUNCTION("""COMPUTED_VALUE"""),"Patt of SO np.15") -> Patt of SO np.15 | F19: =IFERROR(__xludf.DUMMYFUNCTION("""COMPUTED_VALUE"""),"PO ke PT. BSM (vacum tube)") -> PO ke PT. BSM (vacum tube) | G19: =IFERROR(__xludf.DUMMYFUNCTION("""COMPUTED_VALUE"""),45898.0) -> 45898 | I19: =IFERROR(__xludf.DUMMYFUNCTION("""COMPUTED_VALUE"""),425000.0) -> 425000 | J19: =IFERROR(__xludf.DUMMYFUNCTION("""COMPUTED_VALUE"""),46750.0) -> 46750 | L19: =IFERROR(__xludf.DUMMYFUNCTION("""COMPUTED_VALUE"""),471750.0) -> 471750 | M19: 45901 | N19: BCA MPG | O19: 471750 | P19: 45901 | R19: =L19-O19 -> 0 | S19: =IF(R19>0,"ost","-") -> - | T19: -
B20: =IFERROR(__xludf.DUMMYFUNCTION("""COMPUTED_VALUE"""),"Shopee") -> Shopee | C20: =IFERROR(__xludf.DUMMYFUNCTION("""COMPUTED_VALUE"""),"Pembelian Pesanan (PKM Bojong) cover glass dan bisturi") -> Pembelian Pesanan (PKM Bojong) cover glass dan bisturi | E20: =IFERROR(__xludf.DUMMYFUNCTION("""COMPUTED_VALUE"""),"Surat Pesanan PKM Bojong (3 Sep 2025)") -> Surat Pesanan PKM Bojong (3 Sep 2025) | G20: =IFERROR(__xludf.DUMMYFUNCTION("""COMPUTED_VALUE"""),45903.0) -> 45903 | I20: =IFERROR(__xludf.DUMMYFUNCTION("""COMPUTED_VALUE"""),96580.0) -> 96580 | L20: =IFERROR(__xludf.DUMMYFUNCTION("""COMPUTED_VALUE"""),96580.0) -> 96580 | M20: 45903 | N20: BCA MPG | O20: 96580 | P20: 45903 | R20: =L20-O20 -> 0 | S20: =IF(R20>0,"ost","-") -> - | T20: - | U20: WhatsApp Image 2025-09-03 at 17.05.49.jpeg
B21: =IFERROR(__xludf.DUMMYFUNCTION("""COMPUTED_VALUE"""),"Shopee") -> Shopee | C21: =IFERROR(__xludf.DUMMYFUNCTION("""COMPUTED_VALUE"""),"Pembelian Pesanan (PKM Bojong) kassa steril") -> Pembelian Pesanan (PKM Bojong) kassa steril | E21: =IFERROR(__xludf.DUMMYFUNCTION("""COMPUTED_VALUE"""),"Surat Pesanan PKM Bojong (3 Sep 2025)") -> Surat Pesanan PKM Bojong (3 Sep 2025) | G21: =IFERROR(__xludf.DUMMYFUNCTION("""COMPUTED_VALUE"""),45903.0) -> 45903 | I21: =IFERROR(__xludf.DUMMYFUNCTION("""COMPUTED_VALUE"""),402500.0) -> 402500 | L21: =IFERROR(__xludf.DUMMYFUNCTION("""COMPUTED_VALUE"""),402500.0) -> 402500 | M21: 45903 | N21: BCA MPG | O21: 402500 | P21: 45903 | R21: =L21-O21 -> 0 | S21: =IF(R21>0,"ost","-") -> - | T21: - | U21: WhatsApp Image 2025-09-03 at 17.04.58.jpeg
B22: =IFERROR(__xludf.DUMMYFUNCTION("""COMPUTED_VALUE"""),"Toko Pramuka") -> Toko Pramuka | C22: =IFERROR(__xludf.DUMMYFUNCTION("""COMPUTED_VALUE"""),"Pembelian Pesanan (PKM Sentul) 10box Safeguard") -> Pembelian Pesanan (PKM Sentul) 10box Safeguard | E22: =IFERROR(__xludf.DUMMYFUNCTION("""COMPUTED_VALUE"""),"-Menyusul-") -> -Menyusul- | G22: =IFERROR(__xludf.DUMMYFUNCTION("""COMPUTED_VALUE"""),45903.0) -> 45903 | I22: =IFERROR(__xludf.DUMMYFUNCTION("""COMPUTED_VALUE"""),430000.0) -> 430000 | L22: =IFERROR(__xludf.DUMMYFUNCTION("""COMPUTED_VALUE"""),430000.0) -> 430000 | M22: batal | N22: BCA MPG | R22: batal | S22: batal | T22: - | V22: gajadi pesan
B23: =IFERROR(__xludf.DUMMYFUNCTION("""COMPUTED_VALUE"""),"Top Point") -> Top Point | C23: =IFERROR(__xludf.DUMMYFUNCTION("""COMPUTED_VALUE"""),"Pembelian Pesanan (RSPP) PO ke 3 ") -> Pembelian Pesanan (RSPP) PO ke 3 | E23: =IFERROR(__xludf.DUMMYFUNCTION("""COMPUTED_VALUE"""),"Surat Pesanan RSPP (PO 3)") -> Surat Pesanan RSPP (PO 3) | F23: =IFERROR(__xludf.DUMMYFUNCTION("""COMPUTED_VALUE"""),"PO ke Top Point (Pesanan RSPP PO 3)") -> PO ke Top Point (Pesanan RSPP PO 3) | G23: =IFERROR(__xludf.DUMMYFUNCTION("""COMPUTED_VALUE"""),45896.0) -> 45896 | I23: =IFERROR(__xludf.DUMMYFUNCTION("""COMPUTED_VALUE"""),6081081.0) -> 6081081 | J23: =IFERROR(__xludf.DUMMYFUNCTION("""COMPUTED_VALUE"""),668919.0) -> 668919 | L23: =IFERROR(__xludf.DUMMYFUNCTION("""COMPUTED_VALUE"""),6750000.0) -> 6750000 | M23: 45903 | N23: BCA MPG | O23: 6750000 | P23: 45903 | R23: =L23-O23 -> 0 | S23: =IF(R23>0,"ost","-") -> - | T23: - | U23: WhatsApp Image 2025-09-03 at 17.04.35.jpeg
B24: =IFERROR(__xludf.DUMMYFUNCTION("""COMPUTED_VALUE"""),"Top Point") -> Top Point | C24: =IFERROR(__xludf.DUMMYFUNCTION("""COMPUTED_VALUE"""),"Pembelian Kekurangan Stock Suntikan RSUD") -> Pembelian Kekurangan Stock Suntikan RSUD | E24: =IFERROR(__xludf.DUMMYFUNCTION("""COMPUTED_VALUE"""),"Surat Pesanan Suntikan RSUD Cibinong") -> Surat Pesanan Suntikan RSUD Cibinong | F24: =IFERROR(__xludf.DUMMYFUNCTION("""COMPUTED_VALUE"""),"PO ke TOP POINT (stok suntikan rsud)") -> PO ke TOP POINT (stok suntikan rsud) | G24: =IFERROR(__xludf.DUMMYFUNCTION("""COMPUTED_VALUE"""),45897.0) -> 45897 | I24: =IFERROR(__xludf.DUMMYFUNCTION("""COMPUTED_VALUE"""),3386086.0) -> 3386086 | J24: =IFERROR(__xludf.DUMMYFUNCTION("""COMPUTED_VALUE"""),372469.0) -> 372469 | L24: =IFERROR(__xludf.DUMMYFUNCTION("""COMPUTED_VALUE"""),3758555.0) -> 3758555 | M24: 45903 | N24: BCA MPG | O24: 3758555 | P24: 45903 | R24: =L24-O24 -> 0 | S24: =IF(R24>0,"ost","-") -> - | T24: - | U24: WhatsApp Image 2025-09-03 at 17.04.23.jpeg
B25: =IFERROR(__xludf.DUMMYFUNCTION("""COMPUTED_VALUE"""),"Sarana Megamedilab Sejahtera (SMS)") -> Sarana Megamedilab Sejahtera (SMS) | C25: =IFERROR(__xludf.DUMMYFUNCTION("""COMPUTED_VALUE"""),"Pembelian Reagen RSUD Cibinong (Nodin 15)") -> Pembelian Reagen RSUD Cibinong (Nodin 15) | D25: =IFERROR(__xludf.DUMMYFUNCTION("""COMPUTED_VALUE"""),"SPH RSUD CIBINONG NODIN 15 (1).pdf") -> SPH RSUD CIBINONG NODIN 15 (1).pdf | E25: =IFERROR(__xludf.DUMMYFUNCTION("""COMPUTED_VALUE"""),"nodin 15 rsud cibinong") -> nodin 15 rsud cibinong | F25: =IFERROR(__xludf.DUMMYFUNCTION("""COMPUTED_VALUE"""),"PO ke SMS (nodin 15 RSUD Cibinong)") -> PO ke SMS (nodin 15 RSUD Cibinong) | G25: =IFERROR(__xludf.DUMMYFUNCTION("""COMPUTED_VALUE"""),45876.0) -> 45876 | I25: =IFERROR(__xludf.DUMMYFUNCTION("""COMPUTED_VALUE"""),1.228401E7) -> 12284010 | J25: =IFERROR(__xludf.DUMMYFUNCTION("""COMPUTED_VALUE"""),1351241.0) -> 1351241 | L25: =IFERROR(__xludf.DUMMYFUNCTION("""COMPUTED_VALUE"""),1.3635251E7) -> 13635251 | M25: 45904 | N25: BCA MPG | O25: 13635251 | P25: 45904 | R25: =L25-O25 -> 0 | S25: =IF(R25>0,"ost","-") -> - | T25: -
B26: =IFERROR(__xludf.DUMMYFUNCTION("""COMPUTED_VALUE"""),"PT. Burhan Sejahtera Mulia") -> PT. Burhan Sejahtera Mulia | C26: =IFERROR(__xludf.DUMMYFUNCTION("""COMPUTED_VALUE"""),"Pembelian Pesanan (PKM Bojong) Reagen Asam Urat") -> Pembelian Pesanan (PKM Bojong) Reagen Asam Urat | E26: =IFERROR(__xludf.DUMMYFUNCTION("""COMPUTED_VALUE"""),"part of SO no.20") -> part of SO no.20 | F26: =IFERROR(__xludf.DUMMYFUNCTION("""COMPUTED_VALUE"""),"PO MPG-080925003 BSM.pdf") -> PO MPG-080925003 BSM.pdf | G26: =IFERROR(__xludf.DUMMYFUNCTION("""COMPUTED_VALUE"""),45908.0) -> 45908 | I26: =IFERROR(__xludf.DUMMYFUNCTION("""COMPUTED_VALUE"""),720440.0) -> 720440 | J26: =IFERROR(__xludf.DUMMYFUNCTION("""COMPUTED_VALUE"""),79248.0) -> 79248 | L26: =IFERROR(__xludf.DUMMYFUNCTION("""COMPUTED_VALUE"""),799688.0) -> 799688 | M26: 45908 | N26: BCA MPG | O26: 799688 | P26: 45908 | R26: =L26-O26 -> 0 | S26: =IF(R26>0,"ost","-") -> - | T26: -
B27: =IFERROR(__xludf.DUMMYFUNCTION("""COMPUTED_VALUE"""),"Shopee") -> Shopee | C27: =IFERROR(__xludf.DUMMYFUNCTION("""COMPUTED_VALUE"""),"Pembelanjaan Pesanan Tambahan (PKM Bojong) Carpule dan Plastik Sampah Medis") -> Pembelanjaan Pesanan Tambahan (PKM Bojong) Carpule dan Plastik Sampah Medis | E27: =IFERROR(__xludf.DUMMYFUNCTION("""COMPUTED_VALUE"""),"-Menyusul-") -> -Menyusul- | G27: =IFERROR(__xludf.DUMMYFUNCTION("""COMPUTED_VALUE"""),45908.0) -> 45908 | I27: =IFERROR(__xludf.DUMMYFUNCTION("""COMPUTED_VALUE"""),543000.0) -> 543000 | L27: =IFERROR(__xludf.DUMMYFUNCTION("""COMPUTED_VALUE"""),543000.0) -> 543000 | M27: 45908 | N27: BCA MPG | O27: 543000 | P27: 45908 | R27: =L27-O27 -> 0 | S27: =IF(R27>0,"ost","-") -> - | T27: -
B28: =IFERROR(__xludf.DUMMYFUNCTION("""COMPUTED_VALUE"""),"PT. Tirta Investama") -> PT. Tirta Investama | C28: =IFERROR(__xludf.DUMMYFUNCTION("""COMPUTED_VALUE"""),"Pembaayaran Aqua Galon Gedung") -> Pembaayaran Aqua Galon Gedung | G28: =IFERROR(__xludf.DUMMYFUNCTION("""COMPUTED_VALUE"""),45900.0) -> 45900 | I28: =IFERROR(__xludf.DUMMYFUNCTION("""COMPUTED_VALUE"""),400000.0) -> 400000 | L28: =IFERROR(__xludf.DUMMYFUNCTION("""COMPUTED_VALUE"""),400000.0) -> 400000 | M28: 45908 | N28: BCA MPG | O28: 400000 | P28: 45908 | R28: =L28-O28 -> 0 | S28: =IF(R28>0,"ost","-") -> - | T28: -
B29: =IFERROR(__xludf.DUMMYFUNCTION("""COMPUTED_VALUE"""),"PT. Top Point Medical") -> PT. Top Point Medical | C29: =IFERROR(__xludf.DUMMYFUNCTION("""COMPUTED_VALUE"""),"Pembellian Pesanan (RSPP) PO ke 4") -> Pembellian Pesanan (RSPP) PO ke 4 | E29: =IFERROR(__xludf.DUMMYFUNCTION("""COMPUTED_VALUE"""),"PO KE 4 RSPP") -> PO KE 4 RSPP | F29: =IFERROR(__xludf.DUMMYFUNCTION("""COMPUTED_VALUE"""),"po ke tp (rspp ke 4)") -> po ke tp (rspp ke 4) | G29: =IFERROR(__xludf.DUMMYFUNCTION("""COMPUTED_VALUE"""),45909.0) -> 45909 | I29: =IFERROR(__xludf.DUMMYFUNCTION("""COMPUTED_VALUE"""),4560811.0) -> 4560811 | J29: =IFERROR(__xludf.DUMMYFUNCTION("""COMPUTED_VALUE"""),501689.0) -> 501689 | L29: =IFERROR(__xludf.DUMMYFUNCTION("""COMPUTED_VALUE"""),5062500.0) -> 5062500 | M29: 45915 | N29: BCA MPG | O29: 5062500 | P29: 45915 | R29: =L29-O29 -> 0 | S29: =IF(R29>0,"ost","-") -> - | T29: -
B30: =IFERROR(__xludf.DUMMYFUNCTION("""COMPUTED_VALUE"""),"Gedung") -> Gedung | C30: =IFERROR(__xludf.DUMMYFUNCTION("""COMPUTED_VALUE"""),"Pembayaran Listrik dan Parkir Gedung (pemakaian agustus)") -> Pembayaran Listrik dan Parkir Gedung (pemakaian agustus) | G30: =IFERROR(__xludf.DUMMYFUNCTION("""COMPUTED_VALUE"""),45915.0) -> 45915 | I30: =IFERROR(__xludf.DUMMYFUNCTION("""COMPUTED_VALUE"""),4684781.0) -> 4684781 | L30: =IFERROR(__xludf.DUMMYFUNCTION("""COMPUTED_VALUE"""),4684781.0) -> 4684781 | M30: 45915 | N30: BCA MPG | O30: 4684781 | P30: 45915 | R30: =L30-O30 -> 0 | S30: =IF(R30>0,"ost","-") -> - | T30: -
B31: =IFERROR(__xludf.DUMMYFUNCTION("""COMPUTED_VALUE"""),"Shopee") -> Shopee | C31: =IFERROR(__xludf.DUMMYFUNCTION("""COMPUTED_VALUE"""),"Pembelian Kekurangan Plastik Sampah Medis (PKM Bojong)") -> Pembelian Kekurangan Plastik Sampah Medis (PKM Bojong) | E31: =IFERROR(__xludf.DUMMYFUNCTION("""COMPUTED_VALUE"""),"NOTA PERABOT KANTOR MATA PENSIL 09 25.pdf") -> NOTA PERABOT KANTOR MATA PENSIL 09 25.pdf | G31: =IFERROR(__xludf.DUMMYFUNCTION("""COMPUTED_VALUE"""),45915.0) -> 45915 | I31: =IFERROR(__xludf.DUMMYFUNCTION("""COMPUTED_VALUE"""),53380.0) -> 53380 | L31: =IFERROR(__xludf.DUMMYFUNCTION("""COMPUTED_VALUE"""),53380.0) -> 53380 | M31: 45915 | N31: BCA MPG | O31: 53380 | P31: 45915 | R31: =L31-O31 -> 0 | S31: =IF(R31>0,"ost","-") -> - | T31: -
B32: =IFERROR(__xludf.DUMMYFUNCTION("""COMPUTED_VALUE"""),"Shopee") -> Shopee | C32: =IFERROR(__xludf.DUMMYFUNCTION("""COMPUTED_VALUE"""),"Pembelian Kontrol Kimia (PKM Balekambang)") -> Pembelian Kontrol Kimia (PKM Balekambang) | E32: =IFERROR(__xludf.DUMMYFUNCTION("""COMPUTED_VALUE"""),"Pesanan Balekambang ") -> Pesanan Balekambang | G32: =IFERROR(__xludf.DUMMYFUNCTION("""COMPUTED_VALUE"""),45916.0) -> 45916 | I32: =IFERROR(__xludf.DUMMYFUNCTION("""COMPUTED_VALUE"""),1277500.0) -> 1277500 | L32: =IFERROR(__xludf.DUMMYFUNCTION("""COMPUTED_VALUE"""),1277500.0) -> 1277500 | M32: 45916 | N32: BCA MPG | O32: 1277500 | P32: 45916 | R32: =L32-O32 -> 0 | S32: =IF(R32>0,"ost","-") -> - | T32: -
B33: =IFERROR(__xludf.DUMMYFUNCTION("""COMPUTED_VALUE"""),"Shopee") -> Shopee | C33: =IFERROR(__xludf.DUMMYFUNCTION("""COMPUTED_VALUE"""),"Pembelian Pesanan (PKM Cipeucang)") -> Pembelian Pesanan (PKM Cipeucang) | E33: =IFERROR(__xludf.DUMMYFUNCTION("""COMPUTED_VALUE"""),"Surat Pesanan BMHP PKM Cipeucang.pdf") -> Surat Pesanan BMHP PKM Cipeucang.pdf | G33: =IFERROR(__xludf.DUMMYFUNCTION("""COMPUTED_VALUE"""),45917.0) -> 45917 | I33: =IFERROR(__xludf.DUMMYFUNCTION("""COMPUTED_VALUE"""),2676315.0) -> 2676315 | L33: =IFERROR(__xludf.DUMMYFUNCTION("""COMPUTED_VALUE"""),2676315.0) -> 2676315 | M33: 45917 | N33: BCA MPG | O33: 2676315 | P33: 45917 | R33: =L33-O33 -> 0 | S33: =IF(R33>0,"ost","-") -> - | T33: -
B34: =IFERROR(__xludf.DUMMYFUNCTION("""COMPUTED_VALUE"""),"Shopee") -> Shopee | C34: =IFERROR(__xludf.DUMMYFUNCTION("""COMPUTED_VALUE"""),"Pembelian Pesanan (PKM Kelapa Dua) Plastik Sampah") -> Pembelian Pesanan (PKM Kelapa Dua) Plastik Sampah | E34: =IFERROR(__xludf.DUMMYFUNCTION("""COMPUTED_VALUE"""),"SP Belanja Kebersihan Puskesmas Kelapa Dua September 2025.pdf") -> SP Belanja Kebersihan Puskesmas Kelapa Dua September 2025.pdf | G34: =IFERROR(__xludf.DUMMYFUNCTION("""COMPUTED_VALUE"""),45925.0) -> 45925 | I34: =IFERROR(__xludf.DUMMYFUNCTION("""COMPUTED_VALUE"""),1827490.0) -> 1827490 | L34: =IFERROR(__xludf.DUMMYFUNCTION("""COMPUTED_VALUE"""),1827490.0) -> 1827490 | M34: 45925 | N34: BCA MPG | O34: 1827490 | P34: 45925 | R34: =L34-O34 -> 0 | S34: =IF(R34>0,"ost","-") -> - | T34: -
B35: =IFERROR(__xludf.DUMMYFUNCTION("""COMPUTED_VALUE"""),"Shopee") -> Shopee | C35: =IFERROR(__xludf.DUMMYFUNCTION("""COMPUTED_VALUE"""),"Pembelian Pesanan (PKM Kelapa Dua) Pengharum Ruangan spray dan gantung dahlia") -> Pembelian Pesanan (PKM Kelapa Dua) Pengharum Ruangan spray dan gantung dahlia | E35: =IFERROR(__xludf.DUMMYFUNCTION("""COMPUTED_VALUE"""),"SP Belanja Kebersihan Puskesmas Kelapa Dua September 2025.pdf") -> SP Belanja Kebersihan Puskesmas Kelapa Dua September 2025.pdf | G35: =IFERROR(__xludf.DUMMYFUNCTION("""COMPUTED_VALUE"""),45925.0) -> 45925 | I35: =IFERROR(__xludf.DUMMYFUNCTION("""COMPUTED_VALUE"""),937200.0) -> 937200 | L35: =IFERROR(__xludf.DUMMYFUNCTION("""COMPUTED_VALUE"""),937200.0) -> 937200 | M35: 45925 | N35: BCA MPG | O35: 937200 | P35: 45925 | R35: =L35-O35 -> 0 | S35: =IF(R35>0,"ost","-") -> - | T35: -
B36: =IFERROR(__xludf.DUMMYFUNCTION("""COMPUTED_VALUE"""),"Shopee") -> Shopee | C36: =IFERROR(__xludf.DUMMYFUNCTION("""COMPUTED_VALUE"""),"Pembelian Pesanan (PKM Kelapa Dua) tissue livi dan paseo") -> Pembelian Pesanan (PKM Kelapa Dua) tissue livi dan paseo | E36: =IFERROR(__xludf.DUMMYFUNCTION("""COMPUTED_VALUE"""),"SP Belanja Kebersihan Puskesmas Kelapa Dua September 2025.pdf") -> SP Belanja Kebersihan Puskesmas Kelapa Dua September 2025.pdf | G36: =IFERROR(__xludf.DUMMYFUNCTION("""COMPUTED_VALUE"""),45925.0) -> 45925 | I36: =IFERROR(__xludf.DUMMYFUNCTION("""COMPUTED_VALUE"""),480255.0) -> 480255 | L36: =IFERROR(__xludf.DUMMYFUNCTION("""COMPUTED_VALUE"""),480255.0) -> 480255 | M36: 45925 | N36: BCA MPG | O36: 480255 | P36: 45925 | R36: =L36-O36 -> 0 | S36: =IF(R36>0,"ost","-") -> - | T36: -
B37: =IFERROR(__xludf.DUMMYFUNCTION("""COMPUTED_VALUE"""),"Shopee") -> Shopee | C37: =IFERROR(__xludf.DUMMYFUNCTION("""COMPUTED_VALUE"""),"Pembelian Pesanan (PKM Kelapa Dua) Baygon") -> Pembelian Pesanan (PKM Kelapa Dua) Baygon | E37: =IFERROR(__xludf.DUMMYFUNCTION("""COMPUTED_VALUE"""),"SP Belanja Kebersihan Puskesmas Kelapa Dua September 2025.pdf") -> SP Belanja Kebersihan Puskesmas Kelapa Dua September 2025.pdf | G37: =IFERROR(__xludf.DUMMYFUNCTION("""COMPUTED_VALUE"""),45925.0) -> 45925 | I37: =IFERROR(__xludf.DUMMYFUNCTION("""COMPUTED_VALUE"""),798000.0) -> 798000 | L37: =IFERROR(__xludf.DUMMYFUNCTION("""COMPUTED_VALUE"""),798000.0) -> 798000 | M37: 45925 | N37: BCA MPG | O37: 798000 | P37: 45925 | R37: =L37-O37 -> 0 | S37: =IF(R37>0,"ost","-") -> - | T37: -
B38: =IFERROR(__xludf.DUMMYFUNCTION("""COMPUTED_VALUE"""),"Shopee") -> Shopee | C38: =IFERROR(__xludf.DUMMYFUNCTION("""COMPUTED_VALUE"""),"Pembelian Pesanan (PKM Kelapa Dua) switzal dan minyak telon") -> Pembelian Pesanan (PKM Kelapa Dua) switzal dan minyak telon | E38: =IFERROR(__xludf.DUMMYFUNCTION("""COMPUTED_VALUE"""),"SP Belanja Kebersihan Puskesmas Kelapa Dua September 2025.pdf") -> SP Belanja Kebersihan Puskesmas Kelapa Dua September 2025.pdf | G38: =IFERROR(__xludf.DUMMYFUNCTION("""COMPUTED_VALUE"""),45925.0) -> 45925 | I38: =IFERROR(__xludf.DUMMYFUNCTION("""COMPUTED_VALUE"""),493200.0) -> 493200 | L38: =IFERROR(__xludf.DUMMYFUNCTION("""COMPUTED_VALUE"""),493200.0) -> 493200 | M38: 45925 | N38: BCA MPG | O38: 493200 | P38: 45925 | R38: =L38-O38 -> 0 | S38: =IF(R38>0,"ost","-") -> - | T38: -
B39: =IFERROR(__xludf.DUMMYFUNCTION("""COMPUTED_VALUE"""),"Shopee") -> Shopee | C39: =IFERROR(__xludf.DUMMYFUNCTION("""COMPUTED_VALUE"""),"Pembelian Pesanan (PKM Kelapa Dua) kamper") -> Pembelian Pesanan (PKM Kelapa Dua) kamper | E39: =IFERROR(__xludf.DUMMYFUNCTION("""COMPUTED_VALUE"""),"SP Belanja Kebersihan Puskesmas Kelapa Dua September 2025.pdf") -> SP Belanja Kebersihan Puskesmas Kelapa Dua September 2025.pdf | G39: =IFERROR(__xludf.DUMMYFUNCTION("""COMPUTED_VALUE"""),45925.0) -> 45925 | I39: =IFERROR(__xludf.DUMMYFUNCTION("""COMPUTED_VALUE"""),622900.0) -> 622900 | L39: =IFERROR(__xludf.DUMMYFUNCTION("""COMPUTED_VALUE"""),622900.0) -> 622900 | M39: 45925 | N39: BCA MPG | O39: 622900 | P39: 45925 | R39: =L39-O39 -> 0 | S39: =IF(R39>0,"ost","-") -> - | T39: -
B40: =IFERROR(__xludf.DUMMYFUNCTION("""COMPUTED_VALUE"""),"Shopee") -> Shopee | C40: =IFERROR(__xludf.DUMMYFUNCTION("""COMPUTED_VALUE"""),"Pembelian Pesanan (PKM Kelapa Dua) tempat sampah") -> Pembelian Pesanan (PKM Kelapa Dua) tempat sampah | E40: =IFERROR(__xludf.DUMMYFUNCTION("""COMPUTED_VALUE"""),"SP Belanja Kebersihan Puskesmas Kelapa Dua September 2025.pdf") -> SP Belanja Kebersihan Puskesmas Kelapa Dua September 2025.pdf | G40: =IFERROR(__xludf.DUMMYFUNCTION("""COMPUTED_VALUE"""),45925.0) -> 45925 | I40: =IFERROR(__xludf.DUMMYFUNCTION("""COMPUTED_VALUE"""),432000.0) -> 432000 | L40: =IFERROR(__xludf.DUMMYFUNCTION("""COMPUTED_VALUE"""),432000.0) -> 432000 | M40: 45925 | N40: BCA MPG | O40: 432000 | P40: 45925 | R40: =L40-O40 -> 0 | S40: =IF(R40>0,"ost","-") -> - | T40: -
...

Sheet Sheet3
G6: Pemerintah | H6: Pemungut
D9: laptop | E9: 1000000
D10: mouse | E10: 500000
D11: Total | E11: =E9+E10 -> 1500000
D13: DPP | E13: =E11/1.11 -> 1351351.4 | F13: ini setara nilai invoice
D14: PPN | E14: =E13*11% -> 148648.65 | F14: 0.11 | G14: 0.12
D15: PPH | E15: =E13*1.5% -> 20270.27 | F15: 0.015
D16: NET RECEIPT | E16: =E13-E14-E15 -> 1182432.4
D18: DPP LAIINYA | E18: =E13*11/12 -> 1238738.7
D19: PPN | E19: =E18*12% -> 148648.65

Sheet JE
A2: AC No. | B2: Account Name | C2: Dr. | D2: Cr.
B3: Purchases Journal
A4: 50100-00 | B4: Pembelian | C4: =PURCHASES!L377 -> 1476737831
A5: 22104-00 | B5: Hutang PPh 23 | D5: =PURCHASES!K380
A6: 11411 | B6: Value added tax-input | C6: =PURCHASES!J380
A7: 21111 | B7: Trade payables-Rp | D7: =SUM(C4:C7)-SUM(D4:D6) -> 1476737831
H16: Pada saat beli
I18: Pembelian | K18: 10
J19: hutang | L19: 10
C23: =SUM(C4:C22) -> 1476737831 | D23: =SUM(D4:D22) -> 1476737831 | I23: Hutang | K23: 10
J24: BCA | L24: 10

Sheet Margin
